Workbook

Sheet Complete List
A1: Size | B1: Number | C1: Name | D1: Amount (₹) | E1: Payment Mode | F1: Cash Amount (₹) | G1: GPay Amount (₹) | H1: Name (English)
A2: 44 | B2: {=IF(A2:A1007="", "", COUNTIFS(A2:A1007, A2:A1007, ROW(A2:A1007), "<="&ROW(A2:A1007)))} -> 1 | C2: राहुल राऊत | D2: 200 | E2: Cash | F2: =IF(E2="Cash", D2, 0) -> 200 | G2: =IF(E2="GPay", D2, 0) -> 0 | H2: =IFERROR(__xludf.DUMMYFUNCTION("IF(C2="""","""", GOOGLETRANSLATE(C2, ""auto"", ""en""))"),"Rahul Raut") -> Rahul Raut
A3: 44 | B3: 2 | C3: वेदांत तांडेल | D3: 0 | F3: =IF(E3="Cash", D3, 0) -> 0 | G3: =IF(E3="GPay", D3, 0) -> 0 | H3: =IFERROR(__xludf.DUMMYFUNCTION("IF(C3="""","""", GOOGLETRANSLATE(C3, ""auto"", ""en""))"),"Vedanta Tandel ") -> Vedanta Tandel
A4: 44 | B4: 3 | C4: राहुल नाईक | D4: 350 | E4: GPay | F4: =IF(E4="Cash", D4, 0) -> 0 | G4: =IF(E4="GPay", D4, 0) -> 350 | H4: =IFERROR(__xludf.DUMMYFUNCTION("IF(C4="""","""", GOOGLETRANSLATE(C4, ""auto"", ""en""))"),"Rahul Naik") -> Rahul Naik
A5: 44 | B5: 4 | C5: भावनेश मेहेर | D5: 350 | E5: GPay | F5: =IF(E5="Cash", D5, 0) -> 0 | G5: =IF(E5="GPay", D5, 0) -> 350 | H5: =IFERROR(__xludf.DUMMYFUNCTION("IF(C5="""","""", GOOGLETRANSLATE(C5, ""auto"", ""en""))"),"Bhavnesh Meher") -> Bhavnesh Meher
A6: 44 | B6: 5 | C6: भावनेश मेहेर | D6: 350 | E6: GPay | F6: =IF(E6="Cash", D6, 0) -> 0 | G6: =IF(E6="GPay", D6, 0) -> 350 | H6: =IFERROR(__xludf.DUMMYFUNCTION("IF(C6="""","""", GOOGLETRANSLATE(C6, ""auto"", ""en""))"),"Bhavnesh Meher") -> Bhavnesh Meher
A7: 46 | B7: 1 | C7: मनीष मेहेर | D7: 350 | E7: Cash | F7: =IF(E7="Cash", D7, 0) -> 350 | G7: =IF(E7="GPay", D7, 0) -> 0 | H7: =IFERROR(__xludf.DUMMYFUNCTION("IF(C7="""","""", GOOGLETRANSLATE(C7, ""auto"", ""en""))"),"Manish Meher") -> Manish Meher
A8: 42 | B8: 1 | C8: सुनील चौधरी | D8: 350 | E8: GPay | F8: =IF(E8="Cash", D8, 0) -> 0 | G8: =IF(E8="GPay", D8, 0) -> 350 | H8: =IFERROR(__xludf.DUMMYFUNCTION("IF(C8="""","""", GOOGLETRANSLATE(C8, ""auto"", ""en""))"),"Sunil Chaudhary") -> Sunil Chaudhary
A9: 42 | B9: 2 | C9: जन्मेश तांडेल | D9: 0 | F9: =IF(E9="Cash", D9, 0) -> 0 | G9: =IF(E9="GPay", D9, 0) -> 0 | H9: =IFERROR(__xludf.DUMMYFUNCTION("IF(C9="""","""", GOOGLETRANSLATE(C9, ""auto"", ""en""))"),"Janmesh Tandel") -> Janmesh Tandel
A10: 42 | B10: 3 | C10: रोहन तरे | D10: 200 | E10: Cash | F10: =IF(E10="Cash", D10, 0) -> 200 | G10: =IF(E10="GPay", D10, 0) -> 0 | H10: =IFERROR(__xludf.DUMMYFUNCTION("IF(C10="""","""", GOOGLETRANSLATE(C10, ""auto"", ""en""))"),"Rohan Tare") -> Rohan Tare
A11: 42 | B11: 4 | C11: अजय दादोडे | D11: 200 | E11: Cash | F11: =IF(E11="Cash", D11, 0) -> 0 | G11: =IF(E11="GPay", D11, 0) -> 0 | H11: =IFERROR(__xludf.DUMMYFUNCTION("IF(C11="""","""", GOOGLETRANSLATE(C11, ""auto"", ""en""))"),"Ajay Dadode") -> Ajay Dadode
A12: 42 | B12: 5 | C12: निलेश मेहेर | D12: 200 | E12: GPay | F12: =IF(E12="Cash", D12, 0) -> 0 | G12: =IF(E12="GPay", D12, 0) -> 200 | H12: =IFERROR(__xludf.DUMMYFUNCTION("IF(C12="""","""", GOOGLETRANSLATE(C12, ""auto"", ""en""))"),"Nilesh Meher") -> Nilesh Meher
A13: 42 | B13: 6 | C13: अतुल तांडेल | D13: 350 | E13: GPay | F13: =IF(E13="Cash", D13, 0) -> 0 | G13: =IF(E13="GPay", D13, 0) -> 350 | H13: =IFERROR(__xludf.DUMMYFUNCTION("IF(C13="""","""", GOOGLETRANSLATE(C13, ""auto"", ""en""))"),"Atul Tandel") -> Atul Tandel
A14: 42 | B14: 7 | C14: विनु केणी | F14: =IF(E14="Cash", D14, 0) -> 0 | G14: =IF(E14="GPay", D14, 0) -> 0 | H14: =IFERROR(__xludf.DUMMYFUNCTION("IF(C14="""","""", GOOGLETRANSLATE(C14, ""auto"", ""en""))"),"Vinu Keni") -> Vinu Keni
A15: 42 | B15: 8 | C15: अमोल राऊत | D15: 200 | E15: GPay | F15: =IF(E15="Cash", D15, 0) -> 0 | G15: =IF(E15="GPay", D15, 0) -> 200 | H15: =IFERROR(__xludf.DUMMYFUNCTION("IF(C15="""","""", GOOGLETRANSLATE(C15, ""auto"", ""en""))"),"Amol Raut") -> Amol Raut
A16: 42 | B16: 9 | C16: जिग्नेश चौधरी | D16: 200 | E16: GPay | F16: =IF(E16="Cash", D16, 0) -> 0 | G16: =IF(E16="GPay", D16, 0) -> 200 | H16: =IFERROR(__xludf.DUMMYFUNCTION("IF(C16="""","""", GOOGLETRANSLATE(C16, ""auto"", ""en""))"),"Jignesh Chaudhary") -> Jignesh Chaudhary
A17: 42 | B17: 10 | C17: निखिल मेहेर | D17: 350 | F17: =IF(E17="Cash", D17, 0) -> 0 | G17: =IF(E17="GPay", D17, 0) -> 0 | H17: =IFERROR(__xludf.DUMMYFUNCTION("IF(C17="""","""", GOOGLETRANSLATE(C17, ""auto"", ""en""))"),"Nikhil Meher") -> Nikhil Meher
A18: 42 | B18: 11 | C18: देव | D18: 0 | F18: =IF(E18="Cash", D18, 0) -> 0 | G18: =IF(E18="GPay", D18, 0) -> 0 | H18: =IFERROR(__xludf.DUMMYFUNCTION("IF(C18="""","""", GOOGLETRANSLATE(C18, ""auto"", ""en""))"),"God") -> God
A19: 42 | B19: 12 | C19: अतुल तांडेल | D19: 200 | E19: GPay | F19: =IF(E19="Cash", D19, 0) -> 0 | G19: =IF(E19="GPay", D19, 0) -> 200 | H19: =IFERROR(__xludf.DUMMYFUNCTION("IF(C19="""","""", GOOGLETRANSLATE(C19, ""auto"", ""en""))"),"Atul Tandel") -> Atul Tandel
A20: 42 | B20: 13 | C20: योगेश धनु | D20: 200 | E20: Cash | F20: =IF(E20="Cash", D20, 0) -> 200 | G20: =IF(E20="GPay", D20, 0) -> 0 | H20: =IFERROR(__xludf.DUMMYFUNCTION("IF(C20="""","""", GOOGLETRANSLATE(C20, ""auto"", ""en""))"),"Yogesh Sagittarius ") -> Yogesh Sagittarius
A21: 42 | B21: 14 | C21: सागर दवणे | D21: 0 | F21: =IF(E21="Cash", D21, 0) -> 0 | G21: =IF(E21="GPay", D21, 0) -> 0 | H21: =IFERROR(__xludf.DUMMYFUNCTION("IF(C21="""","""", GOOGLETRANSLATE(C21, ""auto"", ""en""))"),"Ocean drowning") -> Ocean drowning
A22: 42 | B22: 15 | C22: प्रणाली पाटील | D22: 350 | E22: GPay | F22: =IF(E22="Cash", D22, 0) -> 0 | G22: =IF(E22="GPay", D22, 0) -> 350 | H22: =IFERROR(__xludf.DUMMYFUNCTION("IF(C22="""","""", GOOGLETRANSLATE(C22, ""auto"", ""en""))"),"System Patil") -> System Patil
A23: 42 | B23: 16 | C23: तृणाल तरे | D23: 200 | E23: Cash | F23: =IF(E23="Cash", D23, 0) -> 200 | G23: =IF(E23="GPay", D23, 0) -> 0 | H23: =IFERROR(__xludf.DUMMYFUNCTION("IF(C23="""","""", GOOGLETRANSLATE(C23, ""auto"", ""en""))"),"Trinal Tare") -> Trinal Tare
A24: 42 | B24: 17 | C24: अक्षय चौधरी | D24: 200 | E24: GPay | F24: =IF(E24="Cash", D24, 0) -> 0 | G24: =IF(E24="GPay", D24, 0) -> 200 | H24: =IFERROR(__xludf.DUMMYFUNCTION("IF(C24="""","""", GOOGLETRANSLATE(C24, ""auto"", ""en""))"),"Akshay Chaudhary") -> Akshay Chaudhary
A25: 42 | B25: 18 | C25: सार्थक दवणे | D25: 350 | E25: GPay | F25: =IF(E25="Cash", D25, 0) -> 0 | G25: =IF(E25="GPay", D25, 0) -> 350 | H25: =IFERROR(__xludf.DUMMYFUNCTION("IF(C25="""","""", GOOGLETRANSLATE(C25, ""auto"", ""en""))"),"Worthy of praise") -> Worthy of praise
A26: 42 | B26: 19 | C26: भावनेश मेहेर | D26: 350 | E26: GPay | F26: =IF(E26="Cash", D26, 0) -> 0 | G26: =IF(E26="GPay", D26, 0) -> 350 | H26: =IFERROR(__xludf.DUMMYFUNCTION("IF(C26="""","""", GOOGLETRANSLATE(C26, ""auto"", ""en""))"),"Bhavnesh Meher") -> Bhavnesh Meher
A27: 42 | B27: 20 | C27: वैभव राऊत | D27: 250 | E27: GPay | F27: =IF(E27="Cash", D27, 0) -> 0 | G27: =IF(E27="GPay", D27, 0) -> 250 | H27: =IFERROR(__xludf.DUMMYFUNCTION("IF(C27="""","""", GOOGLETRANSLATE(C27, ""auto"", ""en""))"),"Vaibhav Raut") -> Vaibhav Raut
A28: 42 | B28: 21 | C28: मानवेंद्र चौधरी | D28: 200 | E28: Cash | F28: 200
A29: 42 | B29: 22 | C29: हर्षित तांडेल | F29: =IF(E29="Cash", D29, 0) -> 0 | G29: =IF(E29="GPay", D29, 0) -> 0 | H29: =IFERROR(__xludf.DUMMYFUNCTION("IF(C29="""","""", GOOGLETRANSLATE(C29, ""auto"", ""en""))"),"Harshit Tandel") -> Harshit Tandel
A30: 40 | B30: 1 | C30: ॐ धानमेहर | D30: 200 | E30: GPay | F30: =IF(E30="Cash", D30, 0) -> 0 | G30: =IF(E30="GPay", D30, 0) -> 200 | H30: =IFERROR(__xludf.DUMMYFUNCTION("IF(C30="""","""", GOOGLETRANSLATE(C30, ""auto"", ""en""))"),"ॐ Dhanmehar ") -> ॐ Dhanmehar
A31: 40 | B31: 2 | C31: दिशांत तांडेल | D31: 350 | E31: Cash | F31: =IF(E31="Cash", D31, 0) -> 350 | G31: =IF(E31="GPay", D31, 0) -> 0 | H31: =IFERROR(__xludf.DUMMYFUNCTION("IF(C31="""","""", GOOGLETRANSLATE(C31, ""auto"", ""en""))"),"Direction Tandel ") -> Direction Tandel
A32: 40 | B32: 3 | C32: जन्मेश राऊत | D32: 200 | E32: GPay | F32: =IF(E32="Cash", D32, 0) -> 0 | G32: =IF(E32="GPay", D32, 0) -> 200 | H32: =IFERROR(__xludf.DUMMYFUNCTION("IF(C32="""","""", GOOGLETRANSLATE(C32, ""auto"", ""en""))"),"Janmesh Raut") -> Janmesh Raut
A33: 40 | B33: 4 | C33: जन्मेश राऊत | D33: 200 | E33: GPay | F33: =IF(E33="Cash", D33, 0) -> 0 | G33: =IF(E33="GPay", D33, 0) -> 200 | H33: =IFERROR(__xludf.DUMMYFUNCTION("IF(C33="""","""", GOOGLETRANSLATE(C33, ""auto"", ""en""))"),"Janmesh Raut") -> Janmesh Raut
A34: 40 | B34: 5 | C34: रोहन चौधरी | D34: 0 | F34: =IF(E34="Cash", D34, 0) -> 0 | G34: =IF(E34="GPay", D34, 0) -> 0 | H34: =IFERROR(__xludf.DUMMYFUNCTION("IF(C34="""","""", GOOGLETRANSLATE(C34, ""auto"", ""en""))"),"Rohan Chowdhary") -> Rohan Chowdhary
A35: 40 | B35: 6 | C35: निकेत चौधरी | D35: 350 | E35: GPay | F35: =IF(E35="Cash", D35, 0) -> 0 | G35: =IF(E35="GPay", D35, 0) -> 350 | H35: =IFERROR(__xludf.DUMMYFUNCTION("IF(C35="""","""", GOOGLETRANSLATE(C35, ""auto"", ""en""))"),"Niket Choudhary") -> Niket Choudhary
A36: 40 | B36: 7 | C36: निकेत चौधरी | D36: 350 | E36: GPay | F36: =IF(E36="Cash", D36, 0) -> 0 | G36: =IF(E36="GPay", D36, 0) -> 350 | H36: =IFERROR(__xludf.DUMMYFUNCTION("IF(C36="""","""", GOOGLETRANSLATE(C36, ""auto"", ""en""))"),"Niket Choudhary") -> Niket Choudhary
A37: 40 | B37: 8 | C37: चेतन तरे | D37: 200 | E37: Cash | F37: =IF(E37="Cash", D37, 0) -> 200 | G37: =IF(E37="GPay", D37, 0) -> 0 | H37: =IFERROR(__xludf.DUMMYFUNCTION("IF(C37="""","""", GOOGLETRANSLATE(C37, ""auto"", ""en""))"),"conscious stars") -> conscious stars
A38: 40 | B38: 9 | C38: प्रफुल्ल चौधरी | D38: 200 | E38: Cash | F38: =IF(E38="Cash", D38, 0) -> 200 | G38: =IF(E38="GPay", D38, 0) -> 0 | H38: =IFERROR(__xludf.DUMMYFUNCTION("IF(C38="""","""", GOOGLETRANSLATE(C38, ""auto"", ""en""))"),"Prafulla Chaudhary") -> Prafulla Chaudhary
A39: 40 | B39: 10 | C39: भावेश चौधरी | D39: 350 | E39: GPay | F39: =IF(E39="Cash", D39, 0) -> 0 | G39: =IF(E39="GPay", D39, 0) -> 350 | H39: =IFERROR(__xludf.DUMMYFUNCTION("IF(C39="""","""", GOOGLETRANSLATE(C39, ""auto"", ""en""))"),"Bhavesh Choudhary") -> Bhavesh Choudhary
A40: 40 | B40: 11 | C40: यश किणी | D40: 200 | E40: Cash | F40: =IF(E40="Cash", D40, 0) -> 200 | G40: =IF(E40="GPay", D40, 0) -> 0 | H40: =IFERROR(__xludf.DUMMYFUNCTION("IF(C40="""","""", GOOGLETRANSLATE(C40, ""auto"", ""en""))"),"Success story") -> Success story
...

Sheet Size Summary
A1: Size | B1: Entries | C1: Total_Amount | D1: Cash | E1: GPay
A2: 46 | B2: =COUNTIF('Complete List'!A$2:A1001, A2) -> 1 | C2: =SUMIF('Complete List'!A$2:A1001, A2, 'Complete List'!D$2:D1001) -> 350 | D2: =SUMIF('Complete List'!A$2:A1001, A2, 'Complete List'!F$2:F1001) -> 350 | E2: =SUMIF('Complete List'!A$2:A1001, A2, 'Complete List'!G$2:G1001) -> 0
A3: 44 | B3: =COUNTIF('Complete List'!A$2:A1001, A3) -> 5 | C3: =SUMIF('Complete List'!A$2:A1001, A3, 'Complete List'!D$2:D1001) -> 1250 | D3: =SUMIF('Complete List'!A$2:A1001, A3, 'Complete List'!F$2:F1001) -> 200 | E3: =SUMIF('Complete List'!A$2:A1001, A3, 'Complete List'!G$2:G1001) -> 1050
A4: 42 | B4: =COUNTIF('Complete List'!A$2:A1001, A4) -> 22 | C4: =SUMIF('Complete List'!A$2:A1001, A4, 'Complete List'!D$2:D1001) -> 4350 | D4: =SUMIF('Complete List'!A$2:A1001, A4, 'Complete List'!F$2:F1001) -> 800 | E4: =SUMIF('Complete List'!A$2:A1001, A4, 'Complete List'!G$2:G1001) -> 3000
A5: 40 | B5: =COUNTIF('Complete List'!A$2:A1001, A5) -> 36 | C5: =SUMIF('Complete List'!A$2:A1001, A5, 'Complete List'!D$2:D1001) -> 6900 | D5: =SUMIF('Complete List'!A$2:A1001, A5, 'Complete List'!F$2:F1001) -> 3150 | E5: =SUMIF('Complete List'!A$2:A1001, A5, 'Complete List'!G$2:G1001) -> 3750
A6: 38 | B6: =COUNTIF('Complete List'!A$2:A1001, A6) -> 30 | C6: =SUMIF('Complete List'!A$2:A1001, A6, 'Complete List'!D$2:D1001) -> 4900 | D6: =SUMIF('Complete List'!A$2:A1001, A6, 'Complete List'!F$2:F1001) -> 2100 | E6: =SUMIF('Complete List'!A$2:A1001, A6, 'Complete List'!G$2:G1001) -> 2800
A7: 36 | B7: =COUNTIF('Complete List'!A$2:A1001, A7) -> 11 | C7: =SUMIF('Complete List'!A$2:A1001, A7, 'Complete List'!D$2:D1001) -> 2000 | D7: =SUMIF('Complete List'!A$2:A1001, A7, 'Complete List'!F$2:F1001) -> 1200 | E7: =SUMIF('Complete List'!A$2:A1001, A7, 'Complete List'!G$2:G1001) -> 800
A8: 32 | B8: =COUNTIF('Complete List'!A$2:A1001, A8) -> 7 | C8: =SUMIF('Complete List'!A$2:A1001, A8, 'Complete List'!D$2:D1001) -> 1450 | D8: =SUMIF('Complete List'!A$2:A1001, A8, 'Complete List'!F$2:F1001) -> 850 | E8: =SUMIF('Complete List'!A$2:A1001, A8, 'Complete List'!G$2:G1001) -> 600
A9: 30 | B9: =COUNTIF('Complete List'!A$2:A1001, A9) -> 5 | C9: =SUMIF('Complete List'!A$2:A1001, A9, 'Complete List'!D$2:D1001) -> 600 | D9: =SUMIF('Complete List'!A$2:A1001, A9, 'Complete List'!F$2:F1001) -> 400 | E9: =SUMIF('Complete List'!A$2:A1001, A9, 'Complete List'!G$2:G1001) -> 200
A10: 28 | B10: =COUNTIF('Complete List'!A$2:A1001, A10) -> 5 | C10: =SUMIF('Complete List'!A$2:A1001, A10, 'Complete List'!D$2:D1001) -> 550 | D10: =SUMIF('Complete List'!A$2:A1001, A10, 'Complete List'!F$2:F1001) -> 350 | E10: =SUMIF('Complete List'!A$2:A1001, A10, 'Complete List'!G$2:G1001) -> 200
A11: 26 | B11: =COUNTIF('Complete List'!A$2:A1001, A11) -> 3 | C11: =SUMIF('Complete List'!A$2:A1001, A11, 'Complete List'!D$2:D1001) -> 400 | D11: =SUMIF('Complete List'!A$2:A1001, A11, 'Complete List'!F$2:F1001) -> 200 | E11: =SUMIF('Complete List'!A$2:A1001, A11, 'Complete List'!G$2:G1001) -> 200
A12: 24 | B12: =COUNTIF('Complete List'!A$2:A1001, A12) -> 10 | C12: =SUMIF('Complete List'!A$2:A1001, A12, 'Complete List'!D$2:D1001) -> 1700 | D12: =SUMIF('Complete List'!A$2:A1001, A12, 'Complete List'!F$2:F1001) -> 500 | E12: =SUMIF('Complete List'!A$2:A1001, A12, 'Complete List'!G$2:G1001) -> 1200
A13: 22 | B13: =COUNTIF('Complete List'!A$2:A1001, A13) -> 7 | C13: =SUMIF('Complete List'!A$2:A1001, A13, 'Complete List'!D$2:D1001) -> 1100 | D13: =SUMIF('Complete List'!A$2:A1001, A13, 'Complete List'!F$2:F1001) -> 450 | E13: =SUMIF('Complete List'!A$2:A1001, A13, 'Complete List'!G$2:G1001) -> 650
A14: 20 | B14: =COUNTIF('Complete List'!A$2:A1001, A14) -> 5 | C14: =SUMIF('Complete List'!A$2:A1001, A14, 'Complete List'!D$2:D1001) -> 900 | D14: =SUMIF('Complete List'!A$2:A1001, A14, 'Complete List'!F$2:F1001) -> 0 | E14: =SUMIF('Complete List'!A$2:A1001, A14, 'Complete List'!G$2:G1001) -> 900
C16: =SUM(C2:C14) -> 26450 | D16: =SUM(D2:D14) -> 10550 | E16: =SUM(E2:E14) -> 15350

Sheet Payment Summary
A1: Payment Mode | B1: Entries | C1: Total_Amount
A2: Cash | B2: =COUNTIF('Complete List'!E$2:E1000, A2) -> 46 | C2: =SUMIF('Complete List'!E$2:E1000, A2, 'Complete List'!D$2:D1000) -> 10750
A3: GPay | B3: =COUNTIF('Complete List'!E$2:E1000, A3) -> 61 | C3: =SUMIF('Complete List'!E$2:E1000, A3, 'Complete List'!D$2:D1000) -> 15350
A4: Pending | B4: =COUNTIF('Complete List'!E$2:E1000, A4) -> 3 | C4: =SUMIF('Complete List'!E$2:E1000, A4, 'Complete List'!D$2:D1000) -> 0
A5: Payment | B5: =COUNTIF('Complete List'!E$2:E1000, A5) -> 0 | C5: =SUMIF('Complete List'!E$2:E1000, A5, 'Complete List'!D$2:D1000) -> 0

Sheet Customer Details
A1: =IFERROR(__xludf.DUMMYFUNCTION("QUERY('Complete List'!A:G, ""SELECT C, A, D, E"", 1)"),"Name") -> Name | B1: =IFERROR(__xludf.DUMMYFUNCTION("""COMPUTED_VALUE"""),"Size") -> Size | C1: =IFERROR(__xludf.DUMMYFUNCTION("""COMPUTED_VALUE"""),"Amount (₹)") -> Amount (₹) | D1: =IFERROR(__xludf.DUMMYFUNCTION("""COMPUTED_VALUE"""),"Payment Mode") -> Payment Mode
A2: =IFERROR(__xludf.DUMMYFUNCTION("""COMPUTED_VALUE"""),"राहुल राऊत ") -> राहुल राऊत | B2: =IFERROR(__xludf.DUMMYFUNCTION("""COMPUTED_VALUE"""),44.0) -> 44 | C2: =IFERROR(__xludf.DUMMYFUNCTION("""COMPUTED_VALUE"""),200.0) -> 200 | D2: =IFERROR(__xludf.DUMMYFUNCTION("""COMPUTED_VALUE"""),"Cash") -> Cash
A3: =IFERROR(__xludf.DUMMYFUNCTION("""COMPUTED_VALUE"""),"वेदांत तांडेल ") -> वेदांत तांडेल | B3: =IFERROR(__xludf.DUMMYFUNCTION("""COMPUTED_VALUE"""),44.0) -> 44 | C3: =IFERROR(__xludf.DUMMYFUNCTION("""COMPUTED_VALUE"""),0.0) -> 0
A4: =IFERROR(__xludf.DUMMYFUNCTION("""COMPUTED_VALUE"""),"राहुल नाईक") -> राहुल नाईक | B4: =IFERROR(__xludf.DUMMYFUNCTION("""COMPUTED_VALUE"""),44.0) -> 44 | C4: =IFERROR(__xludf.DUMMYFUNCTION("""COMPUTED_VALUE"""),350.0) -> 350 | D4: =IFERROR(__xludf.DUMMYFUNCTION("""COMPUTED_VALUE"""),"GPay") -> GPay
A5: =IFERROR(__xludf.DUMMYFUNCTION("""COMPUTED_VALUE"""),"भावनेश मेहेर ") -> भावनेश मेहेर | B5: =IFERROR(__xludf.DUMMYFUNCTION("""COMPUTED_VALUE"""),44.0) -> 44 | C5: =IFERROR(__xludf.DUMMYFUNCTION("""COMPUTED_VALUE"""),350.0) -> 350 | D5: =IFERROR(__xludf.DUMMYFUNCTION("""COMPUTED_VALUE"""),"GPay") -> GPay
A6: =IFERROR(__xludf.DUMMYFUNCTION("""COMPUTED_VALUE"""),"भावनेश मेहेर ") -> भावनेश मेहेर | B6: =IFERROR(__xludf.DUMMYFUNCTION("""COMPUTED_VALUE"""),44.0) -> 44 | C6: =IFERROR(__xludf.DUMMYFUNCTION("""COMPUTED_VALUE"""),350.0) -> 350 | D6: =IFERROR(__xludf.DUMMYFUNCTION("""COMPUTED_VALUE"""),"GPay") -> GPay
A7: =IFERROR(__xludf.DUMMYFUNCTION("""COMPUTED_VALUE"""),"मनीष मेहेर") -> मनीष मेहेर | B7: =IFERROR(__xludf.DUMMYFUNCTION("""COMPUTED_VALUE"""),46.0) -> 46 | C7: =IFERROR(__xludf.DUMMYFUNCTION("""COMPUTED_VALUE"""),350.0) -> 350 | D7: =IFERROR(__xludf.DUMMYFUNCTION("""COMPUTED_VALUE"""),"Cash") -> Cash
A8: =IFERROR(__xludf.DUMMYFUNCTION("""COMPUTED_VALUE"""),"सुनील चौधरी") -> सुनील चौधरी | B8: =IFERROR(__xludf.DUMMYFUNCTION("""COMPUTED_VALUE"""),42.0) -> 42 | C8: =IFERROR(__xludf.DUMMYFUNCTION("""COMPUTED_VALUE"""),350.0) -> 350 | D8: =IFERROR(__xludf.DUMMYFUNCTION("""COMPUTED_VALUE"""),"GPay") -> GPay
A9: =IFERROR(__xludf.DUMMYFUNCTION("""COMPUTED_VALUE"""),"जन्मेश तांडेल ") -> जन्मेश तांडेल | B9: =IFERROR(__xludf.DUMMYFUNCTION("""COMPUTED_VALUE"""),42.0) -> 42 | C9: =IFERROR(__xludf.DUMMYFUNCTION("""COMPUTED_VALUE"""),0.0) -> 0
A10: =IFERROR(__xludf.DUMMYFUNCTION("""COMPUTED_VALUE"""),"रोहन तरे") -> रोहन तरे | B10: =IFERROR(__xludf.DUMMYFUNCTION("""COMPUTED_VALUE"""),42.0) -> 42 | C10: =IFERROR(__xludf.DUMMYFUNCTION("""COMPUTED_VALUE"""),200.0) -> 200 | D10: =IFERROR(__xludf.DUMMYFUNCTION("""COMPUTED_VALUE"""),"Cash") -> Cash
A11: =IFERROR(__xludf.DUMMYFUNCTION("""COMPUTED_VALUE"""),"अजय दादोडे ") -> अजय दादोडे | B11: =IFERROR(__xludf.DUMMYFUNCTION("""COMPUTED_VALUE"""),42.0) -> 42 | C11: =IFERROR(__xludf.DUMMYFUNCTION("""COMPUTED_VALUE"""),200.0) -> 200 | D11: =IFERROR(__xludf.DUMMYFUNCTION("""COMPUTED_VALUE"""),"Cash ") -> Cash
A12: =IFERROR(__xludf.DUMMYFUNCTION("""COMPUTED_VALUE"""),"निलेश मेहेर") -> निलेश मेहेर | B12: =IFERROR(__xludf.DUMMYFUNCTION("""COMPUTED_VALUE"""),42.0) -> 42 | C12: =IFERROR(__xludf.DUMMYFUNCTION("""COMPUTED_VALUE"""),200.0) -> 200 | D12: =IFERROR(__xludf.DUMMYFUNCTION("""COMPUTED_VALUE"""),"GPay") -> GPay
A13: =IFERROR(__xludf.DUMMYFUNCTION("""COMPUTED_VALUE"""),"अतुल तांडेल") -> अतुल तांडेल | B13: =IFERROR(__xludf.DUMMYFUNCTION("""COMPUTED_VALUE"""),42.0) -> 42 | C13: =IFERROR(__xludf.DUMMYFUNCTION("""COMPUTED_VALUE"""),350.0) -> 350 | D13: =IFERROR(__xludf.DUMMYFUNCTION("""COMPUTED_VALUE"""),"GPay") -> GPay
A14: =IFERROR(__xludf.DUMMYFUNCTION("""COMPUTED_VALUE"""),"विनु केणी ") -> विनु केणी | B14: =IFERROR(__xludf.DUMMYFUNCTION("""COMPUTED_VALUE"""),42.0) -> 42
A15: =IFERROR(__xludf.DUMMYFUNCTION("""COMPUTED_VALUE"""),"अमोल राऊत ") -> अमोल राऊत | B15: =IFERROR(__xludf.DUMMYFUNCTION("""COMPUTED_VALUE"""),42.0) -> 42 | C15: =IFERROR(__xludf.DUMMYFUNCTION("""COMPUTED_VALUE"""),200.0) -> 200 | D15: =IFERROR(__xludf.DUMMYFUNCTION("""COMPUTED_VALUE"""),"GPay") -> GPay
A16: =IFERROR(__xludf.DUMMYFUNCTION("""COMPUTED_VALUE"""),"जिग्नेश चौधरी ") -> जिग्नेश चौधरी | B16: =IFERROR(__xludf.DUMMYFUNCTION("""COMPUTED_VALUE"""),42.0) -> 42 | C16: =IFERROR(__xludf.DUMMYFUNCTION("""COMPUTED_VALUE"""),200.0) -> 200 | D16: =IFERROR(__xludf.DUMMYFUNCTION("""COMPUTED_VALUE"""),"GPay") -> GPay
A17: =IFERROR(__xludf.DUMMYFUNCTION("""COMPUTED_VALUE"""),"निखिल मेहेर") -> निखिल मेहेर | B17: =IFERROR(__xludf.DUMMYFUNCTION("""COMPUTED_VALUE"""),42.0) -> 42 | C17: =IFERROR(__xludf.DUMMYFUNCTION("""COMPUTED_VALUE"""),350.0) -> 350
A18: =IFERROR(__xludf.DUMMYFUNCTION("""COMPUTED_VALUE"""),"देव") -> देव | B18: =IFERROR(__xludf.DUMMYFUNCTION("""COMPUTED_VALUE"""),42.0) -> 42 | C18: =IFERROR(__xludf.DUMMYFUNCTION("""COMPUTED_VALUE"""),0.0) -> 0
A19: =IFERROR(__xludf.DUMMYFUNCTION("""COMPUTED_VALUE"""),"अतुल तांडेल ") -> अतुल तांडेल | B19: =IFERROR(__xludf.DUMMYFUNCTION("""COMPUTED_VALUE"""),42.0) -> 42 | C19: =IFERROR(__xludf.DUMMYFUNCTION("""COMPUTED_VALUE"""),200.0) -> 200 | D19: =IFERROR(__xludf.DUMMYFUNCTION("""COMPUTED_VALUE"""),"GPay") -> GPay
A20: =IFERROR(__xludf.DUMMYFUNCTION("""COMPUTED_VALUE"""),"योगेश धनु ") -> योगेश धनु | B20: =IFERROR(__xludf.DUMMYFUNCTION("""COMPUTED_VALUE"""),42.0) -> 42 | C20: =IFERROR(__xludf.DUMMYFUNCTION("""COMPUTED_VALUE"""),200.0) -> 200 | D20: =IFERROR(__xludf.DUMMYFUNCTION("""COMPUTED_VALUE"""),"Cash") -> Cash
A21: =IFERROR(__xludf.DUMMYFUNCTION("""COMPUTED_VALUE"""),"सागर दवणे ") -> सागर दवणे | B21: =IFERROR(__xludf.DUMMYFUNCTION("""COMPUTED_VALUE"""),42.0) -> 42 | C21: =IFERROR(__xludf.DUMMYFUNCTION("""COMPUTED_VALUE"""),0.0) -> 0
A22: =IFERROR(__xludf.DUMMYFUNCTION("""COMPUTED_VALUE"""),"प्रणाली पाटील") -> प्रणाली पाटील | B22: =IFERROR(__xludf.DUMMYFUNCTION("""COMPUTED_VALUE"""),42.0) -> 42 | C22: =IFERROR(__xludf.DUMMYFUNCTION("""COMPUTED_VALUE"""),350.0) -> 350 | D22: =IFERROR(__xludf.DUMMYFUNCTION("""COMPUTED_VALUE"""),"GPay") -> GPay
A23: =IFERROR(__xludf.DUMMYFUNCTION("""COMPUTED_VALUE"""),"तृणाल तरे ") -> तृणाल तरे | B23: =IFERROR(__xludf.DUMMYFUNCTION("""COMPUTED_VALUE"""),42.0) -> 42 | C23: =IFERROR(__xludf.DUMMYFUNCTION("""COMPUTED_VALUE"""),200.0) -> 200 | D23: =IFERROR(__xludf.DUMMYFUNCTION("""COMPUTED_VALUE"""),"Cash") -> Cash
A24: =IFERROR(__xludf.DUMMYFUNCTION("""COMPUTED_VALUE"""),"अक्षय चौधरी") -> अक्षय चौधरी | B24: =IFERROR(__xludf.DUMMYFUNCTION("""COMPUTED_VALUE"""),42.0) -> 42 | C24: =IFERROR(__xludf.DUMMYFUNCTION("""COMPUTED_VALUE"""),200.0) -> 200 | D24: =IFERROR(__xludf.DUMMYFUNCTION("""COMPUTED_VALUE"""),"GPay") -> GPay
A25: =IFERROR(__xludf.DUMMYFUNCTION("""COMPUTED_VALUE"""),"सार्थक दवणे ") -> सार्थक दवणे | B25: =IFERROR(__xludf.DUMMYFUNCTION("""COMPUTED_VALUE"""),42.0) -> 42 | C25: =IFERROR(__xludf.DUMMYFUNCTION("""COMPUTED_VALUE"""),350.0) -> 350 | D25: =IFERROR(__xludf.DUMMYFUNCTION("""COMPUTED_VALUE"""),"GPay") -> GPay
A26: =IFERROR(__xludf.DUMMYFUNCTION("""COMPUTED_VALUE"""),"भावनेश मेहेर ") -> भावनेश मेहेर | B26: =IFERROR(__xludf.DUMMYFUNCTION("""COMPUTED_VALUE"""),42.0) -> 42 | C26: =IFERROR(__xludf.DUMMYFUNCTION("""COMPUTED_VALUE"""),350.0) -> 350 | D26: =IFERROR(__xludf.DUMMYFUNCTION("""COMPUTED_VALUE"""),"GPay") -> GPay
A27: =IFERROR(__xludf.DUMMYFUNCTION("""COMPUTED_VALUE"""),"वैभव राऊत") -> वैभव राऊत | B27: =IFERROR(__xludf.DUMMYFUNCTION("""COMPUTED_VALUE"""),42.0) -> 42 | C27: =IFERROR(__xludf.DUMMYFUNCTION("""COMPUTED_VALUE"""),250.0) -> 250 | D27: =IFERROR(__xludf.DUMMYFUNCTION("""COMPUTED_VALUE"""),"GPay") -> GPay
A28: =IFERROR(__xludf.DUMMYFUNCTION("""COMPUTED_VALUE"""),"मानवेंद्र चौधरी") -> मानवेंद्र चौधरी | B28: =IFERROR(__xludf.DUMMYFUNCTION("""COMPUTED_VALUE"""),42.0) -> 42 | C28: =IFERROR(__xludf.DUMMYFUNCTION("""COMPUTED_VALUE"""),200.0) -> 200 | D28: =IFERROR(__xludf.DUMMYFUNCTION("""COMPUTED_VALUE"""),"Cash") -> Cash
A29: =IFERROR(__xludf.DUMMYFUNCTION("""COMPUTED_VALUE"""),"हर्षित तांडेल") -> हर्षित तांडेल | B29: =IFERROR(__xludf.DUMMYFUNCTION("""COMPUTED_VALUE"""),42.0) -> 42
A30: =IFERROR(__xludf.DUMMYFUNCTION("""COMPUTED_VALUE"""),"ॐ धानमेहर ") -> ॐ धानमेहर | B30: =IFERROR(__xludf.DUMMYFUNCTION("""COMPUTED_VALUE"""),40.0) -> 40 | C30: =IFERROR(__xludf.DUMMYFUNCTION("""COMPUTED_VALUE"""),200.0) -> 200 | D30: =IFERROR(__xludf.DUMMYFUNCTION("""COMPUTED_VALUE"""),"GPay") -> GPay
A31: =IFERROR(__xludf.DUMMYFUNCTION("""COMPUTED_VALUE"""),"दिशांत तांडेल ") -> दिशांत तांडेल | B31: =IFERROR(__xludf.DUMMYFUNCTION("""COMPUTED_VALUE"""),40.0) -> 40 | C31: =IFERROR(__xludf.DUMMYFUNCTION("""COMPUTED_VALUE"""),350.0) -> 350 | D31: =IFERROR(__xludf.DUMMYFUNCTION("""COMPUTED_VALUE"""),"Cash") -> Cash
A32: =IFERROR(__xludf.DUMMYFUNCTION("""COMPUTED_VALUE"""),"जन्मेश राऊत ") -> जन्मेश राऊत | B32: =IFERROR(__xludf.DUMMYFUNCTION("""COMPUTED_VALUE"""),40.0) -> 40 | C32: =IFERROR(__xludf.DUMMYFUNCTION("""COMPUTED_VALUE"""),200.0) -> 200 | D32: =IFERROR(__xludf.DUMMYFUNCTION("""COMPUTED_VALUE"""),"GPay") -> GPay
A33: =IFERROR(__xludf.DUMMYFUNCTION("""COMPUTED_VALUE"""),"जन्मेश राऊत ") -> जन्मेश राऊत | B33: =IFERROR(__xludf.DUMMYFUNCTION("""COMPUTED_VALUE"""),40.0) -> 40 | C33: =IFERROR(__xludf.DUMMYFUNCTION("""COMPUTED_VALUE"""),200.0) -> 200 | D33: =IFERROR(__xludf.DUMMYFUNCTION("""COMPUTED_VALUE"""),"GPay") -> GPay
A34: =IFERROR(__xludf.DUMMYFUNCTION("""COMPUTED_VALUE"""),"रोहन चौधरी") -> रोहन चौधरी | B34: =IFERROR(__xludf.DUMMYFUNCTION("""COMPUTED_VALUE"""),40.0) -> 40 | C34: =IFERROR(__xludf.DUMMYFUNCTION("""COMPUTED_VALUE"""),0.0) -> 0
A35: =IFERROR(__xludf.DUMMYFUNCTION("""COMPUTED_VALUE"""),"निकेत चौधरी ") -> निकेत चौधरी | B35: =IFERROR(__xludf.DUMMYFUNCTION("""COMPUTED_VALUE"""),40.0) -> 40 | C35: =IFERROR(__xludf.DUMMYFUNCTION("""COMPUTED_VALUE"""),350.0) -> 350 | D35: =IFERROR(__xludf.DUMMYFUNCTION("""COMPUTED_VALUE"""),"GPay") -> GPay
A36: =IFERROR(__xludf.DUMMYFUNCTION("""COMPUTED_VALUE"""),"निकेत चौधरी ") -> निकेत चौधरी | B36: =IFERROR(__xludf.DUMMYFUNCTION("""COMPUTED_VALUE"""),40.0) -> 40 | C36: =IFERROR(__xludf.DUMMYFUNCTION("""COMPUTED_VALUE"""),350.0) -> 350 | D36: =IFERROR(__xludf.DUMMYFUNCTION("""COMPUTED_VALUE"""),"GPay") -> GPay
A37: =IFERROR(__xludf.DUMMYFUNCTION("""COMPUTED_VALUE"""),"चेतन तरे") -> चेतन तरे | B37: =IFERROR(__xludf.DUMMYFUNCTION("""COMPUTED_VALUE"""),40.0) -> 40 | C37: =IFERROR(__xludf.DUMMYFUNCTION("""COMPUTED_VALUE"""),200.0) -> 200 | D37: =IFERROR(__xludf.DUMMYFUNCTION("""COMPUTED_VALUE"""),"Cash") -> Cash
A38: =IFERROR(__xludf.DUMMYFUNCTION("""COMPUTED_VALUE"""),"प्रफुल्ल चौधरी") -> प्रफुल्ल चौधरी | B38: =IFERROR(__xludf.DUMMYFUNCTION("""COMPUTED_VALUE"""),40.0) -> 40 | C38: =IFERROR(__xludf.DUMMYFUNCTION("""COMPUTED_VALUE"""),200.0) -> 200 | D38: =IFERROR(__xludf.DUMMYFUNCTION("""COMPUTED_VALUE"""),"Cash") -> Cash
A39: =IFERROR(__xludf.DUMMYFUNCTION("""COMPUTED_VALUE"""),"भावेश चौधरी") -> भावेश चौधरी | B39: =IFERROR(__xludf.DUMMYFUNCTION("""COMPUTED_VALUE"""),40.0) -> 40 | C39: =IFERROR(__xludf.DUMMYFUNCTION("""COMPUTED_VALUE"""),350.0) -> 350 | D39: =IFERROR(__xludf.DUMMYFUNCTION("""COMPUTED_VALUE"""),"GPay") -> GPay
A40: =IFERROR(__xludf.DUMMYFUNCTION("""COMPUTED_VALUE"""),"यश किणी") -> यश किणी | B40: =IFERROR(__xludf.DUMMYFUNCTION("""COMPUTED_VALUE"""),40.0) -> 40 | C40: =IFERROR(__xludf.DUMMYFUNCTION("""COMPUTED_VALUE"""),200.0) -> 200 | D40: =IFERROR(__xludf.DUMMYFUNCTION("""COMPUTED_VALUE"""),"Cash") -> Cash
...
